<?xml version="1.0" encoding="UTF-8"?>
<testng-results skipped="0" failed="1" ignored="0" total="2" passed="1">
  <reporter-output>
  </reporter-output>
  <suite name="Default suite" duration-ms="84" started-at="2019-04-18T14:16:32Z" finished-at="2019-04-18T14:16:32Z">
    <groups>
    </groups>
    <test name="Default test" duration-ms="84" started-at="2019-04-18T14:16:32Z" finished-at="2019-04-18T14:16:32Z">
      <class name="com.yash.siddiqui.MYtestNG">
        <test-method status="FAIL" signature="testSum()[pri:0, instance:com.yash.siddiqui.MYtestNG@2ef5e5e3]" name="testSum" duration-ms="28" started-at="2019-04-18T14:16:32Z" finished-at="2019-04-18T14:16:32Z">
          <exception class="java.lang.AssertionError">
            <message>
              <![CDATA[The following asserts failed:
expected [5] but found [3]]]>
            </message>
            <full-stacktrace>
              <![CDATA[java.lang.AssertionError: The following asserts failed:
expected [5] but found [3]
at org.testng.asserts.SoftAssert.assertAll(SoftAssert.java:43)
at com.yash.siddiqui.MYtestNG.testSum(MYtestNG.java:16)
at sun.reflect.NativeMethodAccessorImpl.invoke0(Native Method)
at sun.reflect.NativeMethodAccessorImpl.invoke(Unknown Source)
at sun.reflect.DelegatingMethodAccessorImpl.invoke(Unknown Source)
at java.lang.reflect.Method.invoke(Unknown Source)
at org.testng.internal.MethodInvocationHelper.invokeMethod(MethodInvocationHelper.java:124)
at org.testng.internal.Invoker.invokeMethod(Invoker.java:580)
at org.testng.internal.Invoker.invokeTestMethod(Invoker.java:716)
at org.testng.internal.Invoker.invokeTestMethods(Invoker.java:988)
at org.testng.internal.TestMethodWorker.invokeTestMethods(TestMethodWorker.java:125)
at org.testng.internal.TestMethodWorker.run(TestMethodWorker.java:109)
at org.testng.TestRunner.privateRun(TestRunner.java:648)
at org.testng.TestRunner.run(TestRunner.java:505)
at org.testng.SuiteRunner.runTest(SuiteRunner.java:455)
at org.testng.SuiteRunner.runSequentially(SuiteRunner.java:450)
at org.testng.SuiteRunner.privateRun(SuiteRunner.java:415)
at org.testng.SuiteRunner.run(SuiteRunner.java:364)
at org.testng.SuiteRunnerWorker.runSuite(SuiteRunnerWorker.java:52)
at org.testng.SuiteRunnerWorker.run(SuiteRunnerWorker.java:84)
at org.testng.TestNG.runSuitesSequentially(TestNG.java:1208)
at org.testng.TestNG.runSuitesLocally(TestNG.java:1137)
at org.testng.TestNG.runSuites(TestNG.java:1049)
at org.testng.TestNG.run(TestNG.java:1017)
at org.testng.remote.AbstractRemoteTestNG.run(AbstractRemoteTestNG.java:114)
at org.testng.remote.RemoteTestNG.initAndRun(RemoteTestNG.java:251)
at org.testng.remote.RemoteTestNG.main(RemoteTestNG.java:77)
]]>
            </full-stacktrace>
          </exception> <!-- java.lang.AssertionError -->
          <reporter-output>
          </reporter-output>
        </test-method> <!-- testSum -->
        <test-method status="PASS" signature="testSum1()[pri:0, instance:com.yash.siddiqui.MYtestNG@2ef5e5e3]" name="testSum1" duration-ms="1" started-at="2019-04-18T14:16:32Z" finished-at="2019-04-18T14:16:32Z">
          <reporter-output>
          </reporter-output>
        </test-method> <!-- testSum1 -->
      </class> <!-- com.yash.siddiqui.MYtestNG -->
    </test> <!-- Default test -->
  </suite> <!-- Default suite -->
</testng-results>
